Workbook

Sheet Overview
A1: HD & LOW — US Comp Sales Point Estimates, Q3 FY2026 – Q2 FY2027
A3: For each forecast quarter, we identify the ONE macro indicator that's historically been the strongest predictor of US comp sales at that exact horizon (see Macro vs Comp Correlation tab), fit a straight line (linear regression, trained on FY2022-present to exclude the pandemic-distorted 2019-2021 period), and plug in that indicator's most recent known reading. Near-term quarters use the 30-year mortgage rate; the two farther-out quarters use Consumer Sentiment, whose predictive power grows sharply with horizon. Full regression detail on the Point Estimates tab. Company guidance and Harvard JCHS's LIRA index are shown below as directional cross-checks only, not blended into the math.
A6: Company | B6: Fiscal Quarter | C6: Predictor Used | D6: Predictor Value | E6: Point Estimate (US Comp %) | F6: LIRA Directional Cross-Check
A7: HD | B7: Q3 FY2026 | C7: Mortgage Rate (Leads 1Q) | D7: ='Point Estimates'!B12 -> 6.4953846 | E7: ='Point Estimates'!B13 -> -0.0072951551 | F7: 0.021
A8: HD | B8: Q4 FY2026 | C8: Mortgage Rate (Leads 2Q) | D8: ='Point Estimates'!B21 -> 6.4953846 | E8: ='Point Estimates'!B22 -> -0.0093849524 | F8: 0.021
A9: HD | B9: Q1 FY2027 | C9: Consumer Sentiment (Leads 4Q) | D9: ='Point Estimates'!B30 -> 52.845055 | E9: ='Point Estimates'!B31 -> -0.027086506 | F9: 0.007
A10: HD | B10: Q2 FY2027 | C10: Consumer Sentiment (Leads 5Q) | D10: ='Point Estimates'!B39 -> 52.845055 | E10: ='Point Estimates'!B40 -> -0.033770653 | F10: 0.005
A11: LOW | B11: Q3 FY2026 | C11: Mortgage Rate (Leads 1Q) | D11: ='Point Estimates'!B51 -> 6.4953846 | E11: ='Point Estimates'!B52 -> -0.016773451 | F11: 0.021
A12: LOW | B12: Q4 FY2026 | C12: Mortgage Rate (Leads 2Q) | D12: ='Point Estimates'!B60 -> 6.4953846 | E12: ='Point Estimates'!B61 -> -0.017023024 | F12: 0.021
A13: LOW | B13: Q1 FY2027 | C13: Consumer Sentiment (Leads 4Q) | D13: ='Point Estimates'!B69 -> 53.102198 | E13: ='Point Estimates'!B70 -> -0.036527661 | F13: 0.007
A14: LOW | B14: Q2 FY2027 | C14: Consumer Sentiment (Leads 5Q) | D14: ='Point Estimates'!B78 -> 53.102198 | E14: ='Point Estimates'!B79 -> -0.056805546 | F14: 0.005
A16: Key Finding: the model diverges from guidance and LIRA
A17: All 8 macro-driven point estimates come out modestly negative, even after excluding the pandemic-distorted 2019-2021 period from training. This is softer than both companies' FY2026 guidance (flat to +2.0% HD, flat LOW) and LIRA's projected direction (positive, decelerating from +2.1% to +0.5%). This is a genuine finding, not a modeling error: a macro-only regression can't see company-specific factors (market share gains, Pro-channel initiatives, HD's SRS acquisition, pricing, store growth) that management's own guidance presumably reflects -- read it as a signal that persistently elevated mortgage rates and soft consumer sentiment are a real headwind guidance may be counting on execution to offset.
A19: FY2026 Guidance Cross-Check
A20: HD | B20: FY2026 total comp sales: flat to +2.0% (reaffirmed 8/18/2026). US comp typically runs slightly below total comp recently (~0.1-0.4 pt gap), so US comp guidance is inferred as roughly flat to +1.7%.
A21: LOW | B21: FY2026 total comp sales: flat (narrowed from flat to +2.0% on 8/19/2026). LOW no longer breaks out US comp separately (divested Canada in FY2022), so total comp guidance applies directly to US comp.
A23: Data sources: US comp sales from HD's/LOW's own quarterly earnings releases. Mortgage rate = Freddie Mac PMMS 30-Yr Fixed weekly average (FRED). Consumer Sentiment = University of Michigan Survey of Consumers (FRED). LIRA = Harvard JCHS, Q2 2026 release. Full source detail and raw series in HD_LOW_Source_Data.xlsx. All public sources. Built 2026-08-20.

Sheet Quarterly Data
A1: HD & LOW — Consolidated Quarterly Data (Comp Sales, Macro Indicators, NAICS444, LIRA)
A2: One row per HD/LOW fiscal quarter. Each company's 30 ACTUAL quarters (Q1 FY2019 - Q2 FY2026) are immediately followed by that SAME company's 4 PROJECTED quarters (Q3 FY2026 - Q2 FY2027, see Period Type column) -- HD rows 5-38, LOW rows 39-72 -- so each company's history reads as one continuous chronological block. Columns E-J (Mortgage Rate through Building Permits) and column K (Data Quality Notes) are sourced from Housing_Macro_Indicators.xlsx's original 'Quarterly Data' tab -- see HD_LOW_Source_Data.xlsx for the raw monthly/weekly readings and day-weighted allocation methodology behind those 6 series (blank for the 4 projected rows -- future macro readings aren't known). Columns L-P (Comp Sales % US, NAICS444, LIRA, Notes, Period Type) are appended after column K. Column L is a hardcoded value (with a source-citing comment) for actual rows, and a LIVE formula linked to the Point Estimates tab for the 4 projected rows per company, so refining the forecast methodology updates these automatically. Built 2026-08-20.
A4: Company | B4: Fiscal Quarter | C4: Quarter Start Date | D4: Quarter End Date | E4: 30-Yr Mortgage Rate (%) | F4: Existing Home Sales (M, SAAR) | G4: New Home Sales (M, SAAR) | H4: CPI-U Index (NSA) | I4: U. Michigan Consumer Sentiment | J4: Building Permits (M Units, SAAR) | K4: Data Quality Notes | L4: Comp Sales % (US) | M4: NAICS444 Retail Sales Y/Y Growth | N4: LIRA Mapped 4-Qtr YoY Rate of Change | O4: Comp / NAICS444 / LIRA Notes | P4: Period Type
A5: HD | B5: Q1 FY2019 | C5: 43500 | D5: 43590 | E5: 4.25 | F5: 5.292967 | G5: 0.68804608 | H5: 254.35782 | I5: 96.828571 | J5: 1.3042857 | K5: All series available as full fiscal-quarter averages. | L5: 0.03 | P5: Actual
A6: HD | B6: Q2 FY2019 | C6: 43591 | D6: 43681 | E6: 3.8646154 | F6: 5.3507692 | G6: 0.66898454 | H6: 256.29247 | I6: 98.413187 | J6: 1.348011 | K6: All series available as full fiscal-quarter averages. | L6: 0.031 | P6: Actual
A7: HD | B7: Q3 FY2019 | C7: 43682 | D7: 43772 | E7: 3.63 | F7: 5.4389011 | G7: 0.71534397 | H7: 256.91413 | I7: 93.093407 | J7: 1.4934286 | K7: All series available as full fiscal-quarter averages. | L7: 0.038 | P7: Actual
A8: HD | B8: Q4 FY2019 | C8: 43773 | D8: 43863 | E8: 3.6753846 | F8: 5.4614286 | G8: 0.70004951 | H8: 257.42052 | I8: 98.765934 | J8: 1.4867033 | K8: All series available as full fiscal-quarter averages. | L8: 0.053 | P8: Actual
A9: HD | B9: Q1 FY2020 | C9: 43864 | D9: 43954 | E9: 3.3992308 | F9: 5.0636264 | G9: 0.63634266 | H9: 257.6563 | I9: 86.373626 | J9: 1.2906703 | K9: All series available as full fiscal-quarter averages. | L9: 0.075 | M9: 0.043498858 | P9: Actual
A10: HD | B10: Q2 FY2020 | C10: 43955 | D10: 44045 | E10: 3.1276923 | F10: 4.8872527 | G10: 0.87110461 | H10: 257.85614 | I10: 74.31978 | J10: 1.3823626 | K10: All series available as full fiscal-quarter averages. | L10: 0.25 | M10: 0.17523525 | P10: Actual
A11: HD | B11: Q3 FY2020 | C11: 44046 | D11: 44136 | E11: 2.8823077 | F11: 6.4751648 | G11: 1.0071598 | H11: 260.20087 | I11: 78.830769 | J11: 1.6005495 | K11: All series available as full fiscal-quarter averages. | L11: 0.246 | M11: 0.16242177 | P11: Actual
A12: HD | B12: Q4 FY2020 | C12: 44137 | D12: 44227 | E12: 2.7246154 | F12: 6.7138462 | G12: 0.883299 | H12: 260.77337 | I12: 78.90989 | J12: 1.7693297 | K12: All series available as full fiscal-quarter averages. | L12: 0.25 | M12: 0.17564951 | P12: Actual
A13: HD | B13: Q1 FY2021 | C13: 44228 | D13: 44318 | E13: 2.99 | F13: 6.0172527 | G13: 0.81287482 | H13: 265.11636 | I13: 83.484615 | J13: 1.7234066 | K13: All series available as full fiscal-quarter averages. | L13: 0.299 | M13: 0.28026534 | P13: Actual
A14: HD | B14: Q2 FY2021 | C14: 44319 | D14: 44409 | E14: 2.93 | F14: 5.8853846 | G14: 0.72516632 | H14: 271.36478 | I14: 83.03956 | J14: 1.6779231 | K14: All series available as full fiscal-quarter averages. | L14: 0.034 | M14: 0.091230187 | P14: Actual
A15: HD | B15: Q3 FY2021 | C15: 44410 | D15: 44500 | E15: 2.9338462 | F15: 6.1718681 | G15: 0.70319032 | H15: 274.84142 | I15: 71.601099 | J15: 1.696033 | K15: All series available as full fiscal-quarter averages. | L15: 0.055 | M15: 0.080830547 | P15: Actual
A16: HD | B16: Q4 FY2021 | C16: 44501 | D16: 44591 | E16: 3.1953846 | F16: 6.3778022 | G16: 0.80247313 | H16: 279.29387 | I16: 68.424176 | J16: 1.859956 | K16: All series available as full fiscal-quarter averages. | L16: 0.076 | M16: 0.13202263 | P16: Actual
A17: HD | B17: Q1 FY2022 | C17: 44592 | D17: 44682 | E17: 4.2953846 | F17: 5.7982418 | G17: 0.70078385 | H17: 286.8504 | I17: 62.432967 | J17: 1.8644066 | K17: All series available as full fiscal-quarter averages. | L17: 0.017 | M17: 0.040642888 | P17: Actual
A18: HD | B18: Q2 FY2022 | C18: 44683 | D18: 44773 | E18: 5.3984615 | F18: 5.11 | G18: 0.57892004 | H18: 294.97545 | I18: 53.28022 | J18: 1.7145824 | K18: All series available as full fiscal-quarter averages. | L18: 0.054 | M18: 0.066951675 | P18: Actual
A19: HD | B19: Q3 FY2022 | C19: 44774 | D19: 44864 | E19: 6.0807692 | F19: 4.6483516 | G19: 0.59101945 | H19: 296.98792 | I19: 58.892308 | J19: 1.5778571 | K19: All series available as full fiscal-quarter averages. | L19: 0.045 | M19: 0.10337001 | P19: Actual
A20: HD | B20: Q4 FY2022 | C20: 44865 | D20: 44955 | E20: 6.4715385 | F20: 4.0412088 | G20: 0.61918355 | H20: 297.8679 | I20: 60.404396 | J20: 1.414978 | K20: All series available as full fiscal-quarter averages. | L20: -0.003 | M20: 0.021008837 | P20: Actual
... A22: HD | B22: Q2 FY2023 | C22: 45047 | D22: 45137 | E22: 6.6638462 | F22: 4.178022 | G22: 0.71708133 | H22: 304.96634 | I22: 64.835165 | J22: 1.5193297 | K22: All series available as full fiscal-quarter averages. | L22: -0.02 | M22: -0.024479818 | P22: Actual
A23: HD | B23: Q3 FY2023 | C23: 45138 | D23: 45228 | E23: 7.28 | F23: 3.9342857 | G23: 0.6721208 | H23: 307.46842 | I23: 67.110989 | J23: 1.5505714 | K23: All series available as full fiscal-quarter averages. | L23: -0.035 | M23: -0.041372021 | N23: 0.044 | P23: Actual
A24: HD | B24: Q4 FY2023 | C24: 45229 | D24: 45319 | E24: 7.0030769 | F24: 3.8610989 | G24: 0.64156766 | H24: 307.38103 | I24: 69.662637 | J24: 1.5199231 | K24: All series available as full fiscal-quarter averages. | L24: -0.04 | M24: -0.043730552 | N24: -0.01 | P24: Actual
A25: HD | B25: Q1 FY2024 | C25: 45320 | D25: 45410 | E25: 6.8561538 | F25: 4.2289011 | G25: 0.67984628 | H25: 311.93781 | I25: 77.913187 | J25: 1.5025165 | K25: All series available as full fiscal-quarter averages. | L25: -0.032 | M25: -0.029585802 | N25: -0.006 | P25: Actual
A26: HD | B26: Q2 FY2024 | C26: 45411 | D26: 45501 | E26: 6.9507692 | F26: 3.9889011 | G26: 0.69406208 | H26: 314.23742 | I26: 68.150549 | J26: 1.4371538 | K26: All series available as full fiscal-quarter averages. | L26: -0.036 | M26: -0.017024035 | N26: -0.023 | P26: Actual
A27: HD | B27: Q3 FY2024 | C27: 45502 | D27: 45592 | E27: 6.3569231 | F27: 3.886044 | G27: 0.68162838 | H27: 315.21158 | I27: 69.347253 | J27: 1.4502308 | K27: All series available as full fiscal-quarter averages. | L27: -0.012 | M27: 0.017002023 | N27: -0.025 | P27: Actual
A28: HD | B28: Q4 FY2024 | C28: 45593 | D28: 45690 | E28: 6.8278571 | F28: 4.1508163 | G28: 0.67605647 | H28: 316.29761 | I28: 72.266327 | J28: 1.4777755 | K28: All series available as full fiscal-quarter averages. | L28: 0.013 | M28: 0.018947587 | N28: -0.019 | P28: Actual
A29: HD | B29: Q1 FY2025 | C29: 45691 | D29: 45781 | E29: 6.7407692 | F29: 4.0824176 | G29: 0.66515004 | H29: 319.99573 | I29: 57.406593 | J29: 1.460022 | K29: All series available as full fiscal-quarter averages. | L29: 0.002 | M29: 0.029038745 | N29: -0.001 | P29: Actual
A30: HD | B30: Q2 FY2025 | C30: 45782 | D30: 45872 | E30: 6.7838462 | F30: 3.9892308 | G30: 0.64762009 | H30: 322.44836 | I30: 58.436264 | J30: 1.4026703 | K30: All series available as full fiscal-quarter averages. | L30: 0.014 | M30: -0.017172492 | N30: 0.012 | P30: Actual
A31: HD | B31: Q3 FY2025 | C31: 45873 | D31: 45963 | E31: 6.3869231 | F31: 4.0567033 | G31: 0.68895358 | H31: 324.41608 | I31: 55.452747 | J31: 1.4046374 | K31: All series available as full fiscal-quarter averages. | L31: 0.001 | M31: -0.034246323 | N31: 0.016 | P31: Actual
A32: HD | B32: Q4 FY2025 | C32: 45964 | D32: 46054 | E32: 6.1776923 | F32: 4.1295604 | G32: 0.68260227 | H32: 324.51304 | I32: 53.548352 | J32: 1.4313956 | K32: All series available as full fiscal-quarter averages. | L32: 0.003 | M32: 0.0044184598 | N32: 0.018 | P32: Actual
A33: HD | B33: Q1 FY2026 | C33: 46055 | D33: 46145 | E33: 6.1969231 | F33: 4.0320879 | G33: 0.64475113 | H33: 330.28315 | I33: 52.845055 | J33: 1.4368462 | K33: All series available as full fiscal-quarter averages. | L33: 0.004 | M33: 0.03792277 | N33: 0.019 | P33: Actual
A34: HD | B34: Q2 FY2026 | C34: 46146 | D34: 46236 | E34: 6.4953846 | K34: Quarter extends beyond available source data for one or more series -- left blank; see the respective 'by Fiscal Qtr' tab. | L34: 0.013 | N34: 0.02 | O34: NAICS444 retail-sales Y/Y growth not yet available (Census reporting lag) | P34: Actual
A35: HD | B35: Q3 FY2026 | C35: 46237 | D35: 46327 | K35: Projected quarter -- macro readings not yet known. | L35: ='Point Estimates'!B13 -> -0.0072951551 | N35: 0.021 | O35: PROJECTED -- see Point Estimates tab for regression detail. | P35: Projected
A36: HD | B36: Q4 FY2026 | C36: 46328 | D36: 46418 | K36: Projected quarter -- macro readings not yet known. | L36: ='Point Estimates'!B22 -> -0.0093849524 | N36: 0.021 | O36: PROJECTED -- see Point Estimates tab for regression detail. | P36: Projected
A37: HD | B37: Q1 FY2027 | C37: 46419 | D37: 46509 | K37: Projected quarter -- macro readings not yet known. | L37: ='Point Estimates'!B31 -> -0.027086506 | N37: 0.007 | O37: PROJECTED -- see Point Estimates tab for regression detail. | P37: Projected
A38: HD | B38: Q2 FY2027 | C38: 46510 | D38: 46600 | K38: Projected quarter -- macro readings not yet known. | L38: ='Point Estimates'!B40 -> -0.033770653 | N38: 0.005 | O38: PROJECTED -- see Point Estimates tab for regression detail. | P38: Projected
A39: LOW | B39: Q1 FY2019 | C39: 43498 | D39: 43588 | E39: 4.25 | F39: 5.2967033 | G39: 0.68869469 | H39: 254.28495 | I39: 96.692308 | J39: 1.3029451 | K39: All series available as full fiscal-quarter averages. | L39: 0.042 | P39: Actual
A40: LOW | B40: Q2 FY2019 | C40: 43589 | D40: 43679 | E40: 3.8646154 | F40: 5.3474725 | G40: 0.66692864 | H40: 256.28223 | I40: 98.637363 | J40: 1.345044 | K40: All series available as full fiscal-quarter averages. | L40: 0.032 | P40: Actual
A41: LOW | B41: Q3 FY2019 | C41: 43680 | D41: 43770 | E41: 3.63 | F41: 5.441978 | G41: 0.71532572 | H41: 256.89985 | I41: 92.93956 | J41: 1.4922637 | K41: All series available as full fiscal-quarter averages. | L41: 0.03 | P41: Actual
A42: LOW | B42: Q4 FY2019 | C42: 43771 | D42: 43861 | E42: 3.6753846 | F42: 5.4521978 | G42: 0.70016789 | H42: 257.38821 | I42: 98.673626 | J42: 1.4883297 | K42: All series available as full fiscal-quarter averages. | L42: 0.026 | P42: Actual
...

Sheet LIRA vs Comp Correlation
A1: LIRA (Harvard JCHS) vs. Comp Sales — Predictive-Power Analysis
A2: Tests whether Harvard JCHS's LIRA four-quarter moving rate of change (homeowner improvements & repairs spend) predicts HD's and LOW's actual reported US comp sales. SIMPLIFYING ASSUMPTION (per explicit user direction): LIRA's calendar-quarter labels are mapped directly to the company fiscal-quarter label of the same number -- e.g. LIRA's "2027-Q2" is treated as corresponding to "Q2 FY2027" for both HD and LOW -- even though the two periods don't actually share identical start/end dates (HD's and LOW's fiscal quarters run roughly one month behind the calendar quarter of the same number). This trades precision for simplicity; see LIRA_Remodeling_Activity.xlsx for LIRA's own calendar-quarter dating. LIRA has only 12 historical quarters (2023-Q3 through 2026-Q2) before turning into Harvard's own projections -- much less than the 25-30 quarters used for the six-macro-series analysis -- so correlation N here is small and results should be read as directional, not as statistically robust. LIRA's 4 projected quarters (2026-Q3 through 2027-Q2) map directly onto the exact 4 quarters HD and LOW need forecasted -- unlike every other series in this workbook, LIRA hands us actual forward-looking values for the full forecast horizon rather than requiring extrapolation. Comp Sales % (US) pulled from HD_LOW_Comp_Sales.xlsx as of 2026-08-20.
A4: LIRA Quarter | B4: Mapped Fiscal Quarter | C4: Period Type | D4: LIRA 4-Qtr Total ($B) | E4: LIRA 4-Qtr YoY Rate of Change | F4: HD Comp % (US) | G4: LOW Comp % (US)
A5: 2023-Q3 | B5: Q3 FY2023 | C5: Historical | D5: 511 | E5: 0.044 | F5: -0.035 | G5: -0.074
A6: 2023-Q4 | B6: Q4 FY2023 | C6: Historical | D6: 510 | E6: -0.01 | F6: -0.04 | G6: -0.062
A7: 2024-Q1 | B7: Q1 FY2024 | C7: Historical | D7: 511 | E7: -0.006 | F7: -0.032 | G7: -0.041
A8: 2024-Q2 | B8: Q2 FY2024 | C8: Historical | D8: 501 | E8: -0.023 | F8: -0.036 | G8: -0.051
A9: 2024-Q3 | B9: Q3 FY2024 | C9: Historical | D9: 498 | E9: -0.025 | F9: -0.012 | G9: -0.011
A10: 2024-Q4 | B10: Q4 FY2024 | C10: Historical | D10: 500 | E10: -0.019 | F10: 0.013 | G10: 0.002
A11: 2025-Q1 | B11: Q1 FY2025 | C11: Historical | D11: 511 | E11: -0.001 | F11: 0.002 | G11: -0.017
A12: 2025-Q2 | B12: Q2 FY2025 | C12: Historical | D12: 507 | E12: 0.012 | F12: 0.014 | G12: 0.011
A13: 2025-Q3 | B13: Q3 FY2025 | C13: Historical | D13: 506 | E13: 0.016 | F13: 0.001 | G13: 0.004
A14: 2025-Q4 | B14: Q4 FY2025 | C14: Historical | D14: 510 | E14: 0.018 | F14: 0.003 | G14: 0.013
A15: 2026-Q1 | B15: Q1 FY2026 | C15: Historical | D15: 520 | E15: 0.019 | F15: 0.004 | G15: 0.006
A16: 2026-Q2 | B16: Q2 FY2026 | C16: Historical | D16: 517 | E16: 0.02 | F16: 0.013 | G16: 0.002
A17: 2026-Q3 | B17: Q3 FY2026 | C17: Projected | D17: 517 | E17: 0.021
A18: 2026-Q4 | B18: Q4 FY2026 | C18: Projected | D18: 520 | E18: 0.021
A19: 2027-Q1 | B19: Q1 FY2027 | C19: Projected | D19: 524 | E19: 0.007
A20: 2027-Q2 | B20: Q2 FY2027 | C20: Projected | D20: 519 | E20: 0.005
A22: Amber italic rows are LIRA's own forward-looking projections (2026-Q3 through 2027-Q2, mapped to Q3 FY2026 - Q2 FY2027) -- no actual comp sales exist yet for these rows since HD and LOW haven't reported them.
A24: Correlation Summary (Pearson r)
A25: Contemporaneous = LIRA's YoY rate of change vs. same-mapped-quarter comp. "LIRA Leads NQ" = this quarter's LIRA reading vs. the comp N quarters ahead. N (quarter count) is shown since it's much smaller than the six-macro-series analysis -- treat r values computed on N<8 with real caution.
A27: Company | B27: Contemporaneous r | C27: Leads 1Q r | D27: Leads 2Q r | E27: Leads 3Q r | F27: N (Contemp.)
A28: HD | B28: =IFERROR(CORREL(E5:E16,F5:F16),"n/a") -> 0.18270146 | C28: =IFERROR(CORREL(E5:E15,F6:F16),"n/a") -> -0.17908647 | D28: =IFERROR(CORREL(E5:E14,F7:F16),"n/a") -> -0.34852809 | E28: =IFERROR(CORREL(E5:E13,F8:F16),"n/a") -> -0.60309273 | F28: =COUNT(F5:F16) -> 12
A29: LOW | B29: =IFERROR(CORREL(E5:E16,G5:G16),"n/a") -> 0.061394834 | C29: =IFERROR(CORREL(E5:E15,G6:G16),"n/a") -> -0.13504804 | D29: =IFERROR(CORREL(E5:E14,G7:G16),"n/a") -> -0.16704725 | E29: =IFERROR(CORREL(E5:E13,G8:G16),"n/a") -> -0.58287727 | F29: =COUNT(G5:G16) -> 12
A31: Key Takeaways
A32: • The correlation is weak at the contemporaneous horizon (HD r=0.18, LOW r=0.06) and turns increasingly NEGATIVE at longer leads (HD -0.60, LOW -0.58 at 3Q) -- the opposite of what we'd hope from the single most conceptually on-topic series in this project. Given N drops to just 9 pairs by the 3Q-lead test, these later figures are especially unstable and should not be read as a reliable trend reversal.
A33: • A few plausible explanations, none of which we can fully rule out with 12 data points: LIRA is a national, all-homeowner remodeling index (much broader than HD/LOW's specific mix of Pro, DIY, and non-remodel categories like appliances); its figures are 4-quarter MOVING totals, which smooths out the quarter-to-quarter variation that actually drives comp-sales swings; and the simplified calendar-to-fiscal-quarter label mapping used here (per user direction) introduces up to a 1-month misalignment that could blur an otherwise real relationship.
A34: • Practical implication for the forecasting model: LIRA should NOT be weighted as a strong regression predictor based on this historical correlation -- it doesn't earn that weight on the evidence. Its real value is different: it's the only series in this project that hands us actual forward-looking figures for the exact 4 quarters we need to forecast, so it's better used as a qualitative/directional cross-check on our forecast's shape (LIRA projects continued modest deceleration through 2027-Q1/Q2) rather than as an input we lean on quantitatively.

Sheet Macro vs Comp Correlation
A1: Macro Indicators vs. Comp Sales — Predictive-Power Analysis
A2: Tests whether the six macro series in this workbook (Mortgage Rate, Existing Home Sales, New Home Sales, CPI-U, U. Michigan Consumer Sentiment, Building Permits) predict HD's and LOW's actual reported US comp sales -- same approach as the NAICS444 retail-sales analysis in HD_LOW_Comp_Sales.xlsx's Analysis tab, applied here to the macro series instead. Comp Sales % (US) values are pulled from HD_LOW_Comp_Sales.xlsx as of 2026-08-20 (see per-cell comments for exact source row); the six macro columns are live formula references to this workbook's Quarterly Data tab. Correlation Summary below computes Pearson r via live CORREL() formulas for six lag structures per series per company: Contemporaneous (same quarter) plus Macro Leads 1Q through 5Q (this quarter's macro reading vs. the comp N quarters ahead -- the directly forecast-usable relationships, since these series don't carry NAICS444's multi-quarter reporting lag; extended one quarter beyond this assignment's 4-quarter forecast horizon as an extra check on how quickly each series' predictive power ultimately decays). CORREL() automatically excludes pairs where either value is blank, so trailing quarters where a series hasn't caught up to the fiscal-quarter-end yet are handled correctly without excluding the whole row.
A4: Home Depot (HD)
A5: Fiscal Quarter | B5: Comp Sales % (US) | C5: Mortgage Rate (%) | D5: Existing Home Sales (M, SAAR) | E5: New Home Sales (M, SAAR) | F5: CPI-U Index (NSA) | G5: Consumer Sentiment | H5: Building Permits (M Units)
A6: Q1 FY2019 | B6: 0.03 | C6: ='Quarterly Data'!E5 -> 4.25 | D6: ='Quarterly Data'!F5 -> 5.292967 | E6: ='Quarterly Data'!G5 -> 0.68804608 | F6: ='Quarterly Data'!H5 -> 254.35782 | G6: ='Quarterly Data'!I5 -> 96.828571 | H6: ='Quarterly Data'!J5 -> 1.3042857
A7: Q2 FY2019 | B7: 0.031 | C7: ='Quarterly Data'!E6 -> 3.8646154 | D7: ='Quarterly Data'!F6 -> 5.3507692 | E7: ='Quarterly Data'!G6 -> 0.66898454 | F7: ='Quarterly Data'!H6 -> 256.29247 | G7: ='Quarterly Data'!I6 -> 98.413187 | H7: ='Quarterly Data'!J6 -> 1.348011
A8: Q3 FY2019 | B8: 0.038 | C8: ='Quarterly Data'!E7 -> 3.63 | D8: ='Quarterly Data'!F7 -> 5.4389011 | E8: ='Quarterly Data'!G7 -> 0.71534397 | F8: ='Quarterly Data'!H7 -> 256.91413 | G8: ='Quarterly Data'!I7 -> 93.093407 | H8: ='Quarterly Data'!J7 -> 1.4934286
A9: Q4 FY2019 | B9: 0.053 | C9: ='Quarterly Data'!E8 -> 3.6753846 | D9: ='Quarterly Data'!F8 -> 5.4614286 | E9: ='Quarterly Data'!G8 -> 0.70004951 | F9: ='Quarterly Data'!H8 -> 257.42052 | G9: ='Quarterly Data'!I8 -> 98.765934 | H9: ='Quarterly Data'!J8 -> 1.4867033
A10: Q1 FY2020 | B10: 0.075 | C10: ='Quarterly Data'!E9 -> 3.3992308 | D10: ='Quarterly Data'!F9 -> 5.0636264 | E10: ='Quarterly Data'!G9 -> 0.63634266 | F10: ='Quarterly Data'!H9 -> 257.6563 | G10: ='Quarterly Data'!I9 -> 86.373626 | H10: ='Quarterly Data'!J9 -> 1.2906703
A11: Q2 FY2020 | B11: 0.25 | C11: ='Quarterly Data'!E10 -> 3.1276923 | D11: ='Quarterly Data'!F10 -> 4.8872527 | E11: ='Quarterly Data'!G10 -> 0.87110461 | F11: ='Quarterly Data'!H10 -> 257.85614 | G11: ='Quarterly Data'!I10 -> 74.31978 | H11: ='Quarterly Data'!J10 -> 1.3823626
A12: Q3 FY2020 | B12: 0.246 | C12: ='Quarterly Data'!E11 -> 2.8823077 | D12: ='Quarterly Data'!F11 -> 6.4751648 | E12: ='Quarterly Data'!G11 -> 1.0071598 | F12: ='Quarterly Data'!H11 -> 260.20087 | G12: ='Quarterly Data'!I11 -> 78.830769 | H12: ='Quarterly Data'!J11 -> 1.6005495
A13: Q4 FY2020 | B13: 0.25 | C13: ='Quarterly Data'!E12 -> 2.7246154 | D13: ='Quarterly Data'!F12 -> 6.7138462 | E13: ='Quarterly Data'!G12 -> 0.883299 | F13: ='Quarterly Data'!H12 -> 260.77337 | G13: ='Quarterly Data'!I12 -> 78.90989 | H13: ='Quarterly Data'!J12 -> 1.7693297
A14: Q1 FY2021 | B14: 0.299 | C14: ='Quarterly Data'!E13 -> 2.99 | D14: ='Quarterly Data'!F13 -> 6.0172527 | E14: ='Quarterly Data'!G13 -> 0.81287482 | F14: ='Quarterly Data'!H13 -> 265.11636 | G14: ='Quarterly Data'!I13 -> 83.484615 | H14: ='Quarterly Data'!J13 -> 1.7234066
A15: Q2 FY2021 | B15: 0.034 | C15: ='Quarterly Data'!E14 -> 2.93 | D15: ='Quarterly Data'!F14 -> 5.8853846 | E15: ='Quarterly Data'!G14 -> 0.72516632 | F15: ='Quarterly Data'!H14 -> 271.36478 | G15: ='Quarterly Data'!I14 -> 83.03956 | H15: ='Quarterly Data'!J14 -> 1.6779231
A16: Q3 FY2021 | B16: 0.055 | C16: ='Quarterly Data'!E15 -> 2.9338462 | D16: ='Quarterly Data'!F15 -> 6.1718681 | E16: ='Quarterly Data'!G15 -> 0.70319032 | F16: ='Quarterly Data'!H15 -> 274.84142 | G16: ='Quarterly Data'!I15 -> 71.601099 | H16: ='Quarterly Data'!J15 -> 1.696033
A17: Q4 FY2021 | B17: 0.076 | C17: ='Quarterly Data'!E16 -> 3.1953846 | D17: ='Quarterly Data'!F16 -> 6.3778022 | E17: ='Quarterly Data'!G16 -> 0.80247313 | F17: ='Quarterly Data'!H16 -> 279.29387 | G17: ='Quarterly Data'!I16 -> 68.424176 | H17: ='Quarterly Data'!J16 -> 1.859956
... A35: Q2 FY2026 | B35: 0.013 | C35: ='Quarterly Data'!E34 -> 6.4953846 | D35: ='Quarterly Data'!F34 -> 0 | E35: ='Quarterly Data'!G34 -> 0 | F35: ='Quarterly Data'!H34 -> 0 | G35: ='Quarterly Data'!I34 -> 0 | H35: ='Quarterly Data'!J34 -> 0
A37: Lowe's (LOW)
A38: Fiscal Quarter | B38: Comp Sales % (US) | C38: Mortgage Rate (%) | D38: Existing Home Sales (M, SAAR) | E38: New Home Sales (M, SAAR) | F38: CPI-U Index (NSA) | G38: Consumer Sentiment | H38: Building Permits (M Units)
A39: Q1 FY2019 | B39: 0.042 | C39: ='Quarterly Data'!E39 -> 4.25 | D39: ='Quarterly Data'!F39 -> 5.2967033 | E39: ='Quarterly Data'!G39 -> 0.68869469 | F39: ='Quarterly Data'!H39 -> 254.28495 | G39: ='Quarterly Data'!I39 -> 96.692308 | H39: ='Quarterly Data'!J39 -> 1.3029451
A40: Q2 FY2019 | B40: 0.032 | C40: ='Quarterly Data'!E40 -> 3.8646154 | D40: ='Quarterly Data'!F40 -> 5.3474725 | E40: ='Quarterly Data'!G40 -> 0.66692864 | F40: ='Quarterly Data'!H40 -> 256.28223 | G40: ='Quarterly Data'!I40 -> 98.637363 | H40: ='Quarterly Data'!J40 -> 1.345044
A41: Q3 FY2019 | B41: 0.03 | C41: ='Quarterly Data'!E41 -> 3.63 | D41: ='Quarterly Data'!F41 -> 5.441978 | E41: ='Quarterly Data'!G41 -> 0.71532572 | F41: ='Quarterly Data'!H41 -> 256.89985 | G41: ='Quarterly Data'!I41 -> 92.93956 | H41: ='Quarterly Data'!J41 -> 1.4922637
A42: Q4 FY2019 | B42: 0.026 | C42: ='Quarterly Data'!E42 -> 3.6753846 | D42: ='Quarterly Data'!F42 -> 5.4521978 | E42: ='Quarterly Data'!G42 -> 0.70016789 | F42: ='Quarterly Data'!H42 -> 257.38821 | G42: ='Quarterly Data'!I42 -> 98.673626 | H42: ='Quarterly Data'!J42 -> 1.4883297
A43: Q1 FY2020 | B43: 0.123 | C43: ='Quarterly Data'!E43 -> 3.3992308 | D43: ='Quarterly Data'!F43 -> 5.1045055 | E43: ='Quarterly Data'!G43 -> 0.63634311 | F43: ='Quarterly Data'!H43 -> 257.70649 | G43: ='Quarterly Data'!I43 -> 87.004396 | H43: ='Quarterly Data'!J43 -> 1.2952857
A44: Q2 FY2020 | B44: 0.351 | C44: ='Quarterly Data'!E44 -> 3.1276923 | D44: ='Quarterly Data'!F44 -> 4.8413187 | E44: ='Quarterly Data'!G44 -> 0.86432457 | F44: ='Quarterly Data'!H44 -> 257.77869 | G44: ='Quarterly Data'!I44 -> 74.28022 | H44: ='Quarterly Data'!J44 -> 1.3761429
A45: Q3 FY2020 | B45: 0.304 | C45: ='Quarterly Data'!E45 -> 2.8823077 | D45: ='Quarterly Data'!F45 -> 6.4582418 | E45: ='Quarterly Data'!G45 -> 1.008521 | F45: ='Quarterly Data'!H45 -> 260.19229 | G45: ='Quarterly Data'!I45 -> 78.715385 | H45: ='Quarterly Data'!J45 -> 1.597956
A46: Q4 FY2020 | B46: 0.286 | C46: ='Quarterly Data'!E46 -> 2.7246154 | D46: ='Quarterly Data'!F46 -> 6.7156044 | E46: ='Quarterly Data'!G46 -> 0.8845058 | F46: ='Quarterly Data'!H46 -> 260.74538 | G46: ='Quarterly Data'!I46 -> 78.917582 | H46: ='Quarterly Data'!J46 -> 1.7648462
A47: Q1 FY2021 | B47: 0.244 | C47: ='Quarterly Data'!E47 -> 2.99 | D47: ='Quarterly Data'!F47 -> 6.0368132 | E47: ='Quarterly Data'!G47 -> 0.81687308 | F47: ='Quarterly Data'!H47 -> 264.94904 | G47: ='Quarterly Data'!I47 -> 83.398901 | H47: ='Quarterly Data'!J47 -> 1.7267253
A48: Q2 FY2021 | B48: -0.022 | C48: ='Quarterly Data'!E48 -> 2.93 | D48: ='Quarterly Data'!F48 -> 5.8824176 | E48: ='Quarterly Data'!G48 -> 0.72517579 | F48: ='Quarterly Data'!H48 -> 271.27489 | G48: ='Quarterly Data'!I48 -> 83.196703 | H48: ='Quarterly Data'!J48 -> 1.677967
A49: Q3 FY2021 | B49: 0.026 | C49: ='Quarterly Data'!E49 -> 2.9338462 | D49: ='Quarterly Data'!F49 -> 6.162967 | E49: ='Quarterly Data'!G49 -> 0.70379013 | F49: ='Quarterly Data'!H49 -> 274.7688 | G49: ='Quarterly Data'!I49 -> 71.69011 | H49: ='Quarterly Data'!J49 -> 1.6961209
A50: Q4 FY2021 | B50: 0.051 | C50: ='Quarterly Data'!E50 -> 3.1953846 | D50: ='Quarterly Data'!F50 -> 6.3742857 | E50: ='Quarterly Data'!G50 -> 0.79983447 | F50: ='Quarterly Data'!H50 -> 279.19367 | G50: ='Quarterly Data'!I50 -> 68.523077 | H50: ='Quarterly Data'!J50 -> 1.855033
... A68: Q2 FY2026 | B68: 0.002 | C68: ='Quarterly Data'!E68 -> 6.4953846 | D68: ='Quarterly Data'!F68 -> 4.1061538 | E68: ='Quarterly Data'!G68 -> 0 | F68: ='Quarterly Data'!H68 -> 334.32646 | G68: ='Quarterly Data'!I68 -> 0 | H68: ='Quarterly Data'!J68 -> 1.4093736
A70: Correlation Summary (Pearson r)
A71: Contemporaneous = macro reading vs. same-quarter comp. "Macro Leads NQ" = this quarter's macro reading vs. the comp N quarters ahead (the relationship usable for an N-quarter-ahead forecast), computed out through 4 quarters to cover the full forecast horizon for this assignment. All use live CORREL() formulas over the full contiguous data range above; blank pairs (a series not yet caught up to a fiscal quarter, or the shift running past the last known quarter) are automatically excluded by CORREL().
A73: Company | B73: Macro Series | C73: Contemporaneous r | D73: Macro Leads 1Q r | E73: Macro Leads 2Q r | F73: Macro Leads 3Q r | G73: Macro Leads 4Q r | H73: Macro Leads 5Q r
A74: HD | B74: Mortgage Rate (%) | C74: =IFERROR(CORREL(C6:C35,B6:B35),"n/a") -> -0.73831236 | D74: =IFERROR(CORREL(C6:C34,B7:B35),"n/a") -> -0.72785101 | E74: =IFERROR(CORREL(C6:C33,B8:B35),"n/a") -> -0.67054583 | F74: =IFERROR(CORREL(C6:C32,B9:B35),"n/a") -> -0.6049121 | G74: =IFERROR(CORREL(C6:C31,B10:B35),"n/a") -> -0.50963476 | H74: =IFERROR(CORREL(C6:C30,B11:B35),"n/a") -> -0.39587727
A75: HD | B75: Existing Home Sales (M, SAAR) | C75: =IFERROR(CORREL(D6:D35,B6:B35),"n/a") -> 0.68968826 | D75: =IFERROR(CORREL(D6:D34,B7:B35),"n/a") -> 0.62319214 | E75: =IFERROR(CORREL(D6:D33,B8:B35),"n/a") -> 0.48695534 | F75: =IFERROR(CORREL(D6:D32,B9:B35),"n/a") -> 0.3278977 | G75: =IFERROR(CORREL(D6:D31,B10:B35),"n/a") -> 0.31396434 | H75: =IFERROR(CORREL(D6:D30,B11:B35),"n/a") -> 0.25035353
A76: HD | B76: New Home Sales (M, SAAR) | C76: =IFERROR(CORREL(E6:E35,B6:B35),"n/a") -> 0.78495671 | D76: =IFERROR(CORREL(E6:E34,B7:B35),"n/a") -> 0.66045282 | E76: =IFERROR(CORREL(E6:E33,B8:B35),"n/a") -> 0.58400063 | F76: =IFERROR(CORREL(E6:E32,B9:B35),"n/a") -> 0.30790872 | G76: =IFERROR(CORREL(E6:E31,B10:B35),"n/a") -> 0.061108414 | H76: =IFERROR(CORREL(E6:E30,B11:B35),"n/a") -> 0.12054741
A77: HD | B77: CPI-U Index (NSA) | C77: =IFERROR(CORREL(F6:F35,B6:B35),"n/a") -> -0.63022201 | D77: =IFERROR(CORREL(F6:F34,B7:B35),"n/a") -> -0.65091092 | E77: =IFERROR(CORREL(F6:F33,B8:B35),"n/a") -> -0.66937367 | F77: =IFERROR(CORREL(F6:F32,B9:B35),"n/a") -> -0.67968631 | G77: =IFERROR(CORREL(F6:F31,B10:B35),"n/a") -> -0.66572551 | H77: =IFERROR(CORREL(F6:F30,B11:B35),"n/a") -> -0.64184532
A78: HD | B78: Consumer Sentiment | C78: =IFERROR(CORREL(G6:G35,B6:B35),"n/a") -> 0.31614759 | D78: =IFERROR(CORREL(G6:G34,B7:B35),"n/a") -> 0.36547366 | E78: =IFERROR(CORREL(G6:G33,B8:B35),"n/a") -> 0.53032866 | F78: =IFERROR(CORREL(G6:G32,B9:B35),"n/a") -> 0.64028478 | G78: =IFERROR(CORREL(G6:G31,B10:B35),"n/a") -> 0.80698809 | H78: =IFERROR(CORREL(G6:G30,B11:B35),"n/a") -> 0.87825302
...

Sheet Point Estimates
A1: Point Estimate Regressions — HD & LOW, Q3 FY2026 – Q2 FY2027
A2: Single-variable linear regression per forecast quarter: SLOPE/INTERCEPT fit comp sales % (Y, column L of the Quarterly Data tab) against ONE macro predictor (X, column E = Mortgage Rate or column I = Consumer Sentiment), using fiscal quarters from Q1 FY2022-present only (the pandemic-distorted 2019-2021 quarters are excluded from training -- an earlier full-sample version produced implausible, sharply negative estimates; see the note below). Point estimate = INTERCEPT + SLOPE x (predictor's most recent known reading).
A4: HD Regressions
A6: Q3 FY2026 (1 quarter ahead) — Mortgage Rate, Leads 1Q
A7: Predictor (X) | B7: 30-Yr Mortgage Rate (%)
A8: N (historical pairs, FY2022+) | B8: =COUNT('Quarterly Data'!E17:E33) -> 17
A9: Slope | B9: =SLOPE('Quarterly Data'!L18:L34,'Quarterly Data'!E17:E33) -> -0.031486994
A10: Intercept | B10: =INTERCEPT('Quarterly Data'!L18:L34,'Quarterly Data'!E17:E33) -> 0.19722498
A11: R (correlation) | B11: =CORREL('Quarterly Data'!L18:L34,'Quarterly Data'!E17:E33) -> -0.7715073
A12: Predictor input (30-Yr Mortgage Rate (%), HD Q2 FY2026) | B12: ='Quarterly Data'!E34 -> 6.4953846
A13: Point Estimate — Q3 FY2026 | B13: =B10+B9*B12 -> -0.0072951551
A15: Q4 FY2026 (2 quarters ahead) — Mortgage Rate, Leads 2Q
A16: Predictor (X) | B16: 30-Yr Mortgage Rate (%)
A17: N (historical pairs, FY2022+) | B17: =COUNT('Quarterly Data'!E17:E32) -> 16
A18: Slope | B18: =SLOPE('Quarterly Data'!L19:L34,'Quarterly Data'!E17:E32) -> -0.016815779
A19: Intercept | B19: =INTERCEPT('Quarterly Data'!L19:L34,'Quarterly Data'!E17:E32) -> 0.099839999
A20: R (correlation) | B20: =CORREL('Quarterly Data'!L19:L34,'Quarterly Data'!E17:E32) -> -0.48386334
A21: Predictor input (30-Yr Mortgage Rate (%), HD Q2 FY2026) | B21: ='Quarterly Data'!E34 -> 6.4953846
A22: Point Estimate — Q4 FY2026 | B22: =B19+B18*B21 -> -0.0093849524
A24: Q1 FY2027 (3 quarters ahead) — Consumer Sentiment, Leads 4Q
A25: Predictor (X) | B25: Consumer Sentiment
A26: N (historical pairs, FY2022+) | B26: =COUNT('Quarterly Data'!I17:I30) -> 14
A27: Slope | B27: =SLOPE('Quarterly Data'!L21:L34,'Quarterly Data'!I17:I30) -> 0.0012661831
A28: Intercept | B28: =INTERCEPT('Quarterly Data'!L21:L34,'Quarterly Data'!I17:I30) -> -0.093998019
A29: R (correlation) | B29: =CORREL('Quarterly Data'!L21:L34,'Quarterly Data'!I17:I30) -> 0.38349463
A30: Predictor input (Consumer Sentiment, HD Q1 FY2026) | B30: ='Quarterly Data'!I33 -> 52.845055
A31: Point Estimate — Q1 FY2027 | B31: =B28+B27*B30 -> -0.027086506
A33: Q2 FY2027 (4 quarters ahead) — Consumer Sentiment, Leads 5Q
A34: Predictor (X) | B34: Consumer Sentiment
A35: N (historical pairs, FY2022+) | B35: =COUNT('Quarterly Data'!I17:I29) -> 13
A36: Slope | B36: =SLOPE('Quarterly Data'!L22:L34,'Quarterly Data'!I17:I29) -> 0.0019768396
A37: Intercept | B37: =INTERCEPT('Quarterly Data'!L22:L34,'Quarterly Data'!I17:I29) -> -0.13823685
A38: R (correlation) | B38: =CORREL('Quarterly Data'!L22:L34,'Quarterly Data'!I17:I29) -> 0.6435584
A39: Predictor input (Consumer Sentiment, HD Q1 FY2026) | B39: ='Quarterly Data'!I33 -> 52.845055
A40: Point Estimate — Q2 FY2027 | B40: =B37+B36*B39 -> -0.033770653
A43: LOW Regressions
A45: Q3 FY2026 (1 quarter ahead) — Mortgage Rate, Leads 1Q
A46: Predictor (X) | B46: 30-Yr Mortgage Rate (%)
A47: N (historical pairs, FY2022+) | B47: =COUNT('Quarterly Data'!E51:E67) -> 17
A48: Slope | B48: =SLOPE('Quarterly Data'!L52:L68,'Quarterly Data'!E51:E67) -> -0.021704772
...

Sheet NAICS444 vs Comp Correlation
A1: NAICS 444 Retail Sales vs. Comp Sales — Correlation Analysis
A2: Tests whether public Census NAICS 444 (Building Material & Garden retail) sales growth predicts HD's and LOW's own reported US comp sales. Uses live CORREL() formulas against this workbook's own 'Quarterly Data' tab (column M = NAICS444 Y/Y growth, column L = Comp Sales % US); blank pairs (no prior-year comparison for the first 4 quarters, or the most recent quarter pending Census reporting) are automatically excluded by CORREL(). Two cuts are shown: the full sample, and a post-pandemic cut starting Q1 FY2022 (the same training window used for the Point Estimates regressions), since the 2020-2021 pandemic demand shock inflates the full-sample correlation for both names.
A4: Correlation Summary (Pearson r)
A5: Contemporaneous = retail growth vs. same-quarter comp. "Retail Leads 1Q" = this quarter's retail growth vs. NEXT quarter's comp (the predictive/forecasting use case). "Retail Lags 1Q" = this quarter's retail growth vs. the PRIOR quarter's comp.
A7: Company | B7: Sample | C7: N (Contemp.) | D7: Contemporaneous r | E7: Retail Leads 1Q r | F7: Retail Lags 1Q r
A8: HD | B8: Full sample | C8: =COUNT('Quarterly Data'!M5:M34) -> 25 | D8: =IFERROR(CORREL('Quarterly Data'!L5:L34,'Quarterly Data'!M5:M34),"n/a") -> 0.92683714 | E8: =IFERROR(CORREL('Quarterly Data'!L6:L34,'Quarterly Data'!M5:M33),"n/a") -> 0.6105798 | F8: =IFERROR(CORREL('Quarterly Data'!L5:L33,'Quarterly Data'!M6:M34),"n/a") -> 0.78697105
A9: HD | B9: Post-pandemic (Q1 FY2022 onward) | C9: =COUNT('Quarterly Data'!M17:M34) -> 17 | D9: =IFERROR(CORREL('Quarterly Data'!L17:L34,'Quarterly Data'!M17:M34),"n/a") -> 0.85626049 | E9: =IFERROR(CORREL('Quarterly Data'!L18:L34,'Quarterly Data'!M17:M33),"n/a") -> 0.59242767 | F9: =IFERROR(CORREL('Quarterly Data'!L17:L33,'Quarterly Data'!M18:M34),"n/a") -> 0.6492782
A11: LOW | B11: Full sample | C11: =COUNT('Quarterly Data'!M39:M68) -> 25 | D11: =IFERROR(CORREL('Quarterly Data'!L39:L68,'Quarterly Data'!M39:M68),"n/a") -> 0.82417261 | E11: =IFERROR(CORREL('Quarterly Data'!L40:L68,'Quarterly Data'!M39:M67),"n/a") -> 0.47726697 | F11: =IFERROR(CORREL('Quarterly Data'!L39:L67,'Quarterly Data'!M40:M68),"n/a") -> 0.79072824
A12: LOW | B12: Post-pandemic (Q1 FY2022 onward) | C12: =COUNT('Quarterly Data'!M51:M68) -> 17 | D12: =IFERROR(CORREL('Quarterly Data'!L51:L68,'Quarterly Data'!M51:M68),"n/a") -> 0.6288473 | E12: =IFERROR(CORREL('Quarterly Data'!L52:L68,'Quarterly Data'!M51:M67),"n/a") -> 0.53113608 | F12: =IFERROR(CORREL('Quarterly Data'!L51:L67,'Quarterly Data'!M52:M68),"n/a") -> 0.33940674
A15: Key Takeaways
A16: • For both names, the contemporaneous (same-quarter) relationship is the strongest of the three tested -- retail sales data and comp sales move together in the same period more than either leads or lags the other, consistent with the earlier version of this analysis (full-sample HD r~0.93, LOW r~0.82).
A17: • HD's correlation with NAICS444 retail sales is consistently stronger and more robust than LOW's, and holds up noticeably better in the post-pandemic cut -- LOW's full-sample correlation is more inflated by the shared 2020-2021 demand shock than HD's.
A18: • Retail data one quarter ahead ("Retail Leads 1Q") is a meaningfully weaker predictor than the same-quarter relationship for both names, reinforcing that NAICS444 works better as a same-quarter nowcast/cross-check than as a forward-looking predictor -- consistent with why it isn't used as a regression input in the Point Estimates tab (Census also reports it with a lag, so it isn't fully available for the most recent quarter anyway).
A19: • Practical implication: NAICS444 is a useful SAME-QUARTER sanity check on comp sales once both are reported (helpful for validating the underlying macro backdrop), but its 1-quarter-lead relationship isn't strong enough on its own to replace the mortgage-rate/consumer-sentiment regressions used for the forward point estimates.
